2019-12-01 11:48:02,066 ERROR: Exception on /home [GET] [in /home/ubuntu/.local/lib/python3.7/site-packages/flask/app.py:1891]
Traceback (most recent call last):
  File "/home/ubuntu/.local/lib/python3.7/site-packages/flask/app.py", line 2446, in wsgi_app
    response = self.full_dispatch_request()
  File "/home/ubuntu/.local/lib/python3.7/site-packages/flask/app.py", line 1951, in full_dispatch_request
    rv = self.handle_user_exception(e)
  File "/home/ubuntu/.local/lib/python3.7/site-packages/flask/app.py", line 1820, in handle_user_exception
    reraise(exc_type, exc_value, tb)
  File "/home/ubuntu/.local/lib/python3.7/site-packages/flask/_compat.py", line 39, in reraise
    raise value
  File "/home/ubuntu/.local/lib/python3.7/site-packages/flask/app.py", line 1949, in full_dispatch_request
    rv = self.dispatch_request()
  File "/home/ubuntu/.local/lib/python3.7/site-packages/flask/app.py", line 1935, in dispatch_request
    return self.view_functions[rule.endpoint](**req.view_args)
  File "/home/ubuntu/.local/lib/python3.7/site-packages/flask_login/utils.py", line 261, in decorated_view
    return func(*args, **kwargs)
  File "/home/ubuntu/blog/app/main/routes.py", line 45, in index
    prev_url=prev_url)
  File "/home/ubuntu/.local/lib/python3.7/site-packages/flask/templating.py", line 140, in render_template
    ctx.app,
  File "/home/ubuntu/.local/lib/python3.7/site-packages/flask/templating.py", line 120, in _render
    rv = template.render(context)
  File "/home/ubuntu/.local/lib/python3.7/site-packages/jinja2/asyncsupport.py", line 76, in render
    return original_render(self, *args, **kwargs)
  File "/home/ubuntu/.local/lib/python3.7/site-packages/jinja2/environment.py", line 1008, in render
    return self.environment.handle_exception(exc_info, True)
  File "/home/ubuntu/.local/lib/python3.7/site-packages/jinja2/environment.py", line 780, in handle_exception
    reraise(exc_type, exc_value, tb)
  File "/home/ubuntu/.local/lib/python3.7/site-packages/jinja2/_compat.py", line 37, in reraise
    raise value.with_traceback(tb)
  File "/home/ubuntu/blog/app/templates/base.html", line 81, in template
    {% block content %}
  File "/home/ubuntu/.local/lib/python3.7/site-packages/jinja2/environment.py", line 1005, in render
    return concat(self.root_render_func(self.new_context(vars)))
  File "/home/ubuntu/blog/app/templates/index.html", line 12, in root
    {% if form %}
  File "/home/ubuntu/.local/lib/python3.7/site-packages/jinja2/environment.py", line 830, in get_template
    return self._load_template(name, self.make_globals(globals))
  File "/home/ubuntu/.local/lib/python3.7/site-packages/jinja2/environment.py", line 804, in _load_template
    template = self.loader.load(self, name, globals)
  File "/home/ubuntu/.local/lib/python3.7/site-packages/jinja2/loaders.py", line 125, in load
    code = environment.compile(source, name, filename)
  File "/home/ubuntu/.local/lib/python3.7/site-packages/jinja2/environment.py", line 591, in compile
    self.handle_exception(exc_info, source_hint=source_hint)
  File "/home/ubuntu/.local/lib/python3.7/site-packages/jinja2/environment.py", line 780, in handle_exception
    reraise(exc_type, exc_value, tb)
  File "/home/ubuntu/.local/lib/python3.7/site-packages/jinja2/_compat.py", line 37, in reraise
    raise value.with_traceback(tb)
  File "/home/ubuntu/blog/app/templates/base.html", line 81, in template
    {% block content %}
  File "/home/ubuntu/.local/lib/python3.7/site-packages/jinja2/environment.py", line 543, in _generate
    optimized=self.optimized)
  File "/home/ubuntu/.local/lib/python3.7/site-packages/jinja2/compiler.py", line 82, in generate
    generator.visit(node)
  File "/home/ubuntu/.local/lib/python3.7/site-packages/jinja2/visitor.py", line 38, in visit
    return f(node, *args, **kwargs)
  File "/home/ubuntu/.local/lib/python3.7/site-packages/jinja2/compiler.py", line 718, in visit_Template
    self.fail('block %r defined twice' % block.name, block.lineno)
  File "/home/ubuntu/.local/lib/python3.7/site-packages/jinja2/compiler.py", line 315, in fail
    raise TemplateAssertionError(msg, lineno, self.name, self.filename)
jinja2.exceptions.TemplateAssertionError: block 'content' defined twice
2019-12-01 11:48:25,996 INFO: 1st Woodhall Blog Startup [in /home/ubuntu/blog/app/__init__.py:66]
2019-12-01 11:49:11,683 INFO: 1st Woodhall Blog Startup [in /home/ubuntu/blog/app/__init__.py:66]
2019-12-01 11:50:27,812 INFO: 1st Woodhall Blog Startup [in /home/ubuntu/blog/app/__init__.py:66]
2019-12-01 11:51:29,384 INFO: 1st Woodhall Blog Startup [in /home/ubuntu/blog/app/__init__.py:66]
2019-12-01 11:52:10,678 INFO: 1st Woodhall Blog Startup [in /home/ubuntu/blog/app/__init__.py:66]
2019-12-01 11:57:51,376 INFO: 1st Woodhall Blog Startup [in /home/ubuntu/blog/app/__init__.py:66]
2019-12-01 11:57:53,474 ERROR: Exception on /auth/login [GET] [in /home/ubuntu/.local/lib/python3.7/site-packages/flask/app.py:1891]
Traceback (most recent call last):
  File "/home/ubuntu/.local/lib/python3.7/site-packages/flask/app.py", line 2446, in wsgi_app
    response = self.full_dispatch_request()
  File "/home/ubuntu/.local/lib/python3.7/site-packages/flask/app.py", line 1951, in full_dispatch_request
    rv = self.handle_user_exception(e)
  File "/home/ubuntu/.local/lib/python3.7/site-packages/flask/app.py", line 1820, in handle_user_exception
    reraise(exc_type, exc_value, tb)
  File "/home/ubuntu/.local/lib/python3.7/site-packages/flask/_compat.py", line 39, in reraise
    raise value
  File "/home/ubuntu/.local/lib/python3.7/site-packages/flask/app.py", line 1949, in full_dispatch_request
    rv = self.dispatch_request()
  File "/home/ubuntu/.local/lib/python3.7/site-packages/flask/app.py", line 1935, in dispatch_request
    return self.view_functions[rule.endpoint](**req.view_args)
  File "/home/ubuntu/blog/app/auth/routes.py", line 28, in login
    return render_template('auth/login.html', title=_('Sign In'), form=form)
  File "/home/ubuntu/.local/lib/python3.7/site-packages/flask/templating.py", line 140, in render_template
    ctx.app,
  File "/home/ubuntu/.local/lib/python3.7/site-packages/flask/templating.py", line 120, in _render
    rv = template.render(context)
  File "/home/ubuntu/.local/lib/python3.7/site-packages/jinja2/asyncsupport.py", line 76, in render
    return original_render(self, *args, **kwargs)
  File "/home/ubuntu/.local/lib/python3.7/site-packages/jinja2/environment.py", line 1008, in render
    return self.environment.handle_exception(exc_info, True)
  File "/home/ubuntu/.local/lib/python3.7/site-packages/jinja2/environment.py", line 780, in handle_exception
    reraise(exc_type, exc_value, tb)
  File "/home/ubuntu/.local/lib/python3.7/site-packages/jinja2/_compat.py", line 37, in reraise
    raise value.with_traceback(tb)
  File "/home/ubuntu/blog/app/templates/base.html", line 80, in template
    {% block content %}
  File "/home/ubuntu/.local/lib/python3.7/site-packages/jinja2/environment.py", line 1005, in render
    return concat(self.root_render_func(self.new_context(vars)))
  File "/home/ubuntu/blog/app/templates/auth/login.html", line 12, in root
    {{ wtf.quick_form(form) }}
  File "/home/ubuntu/.local/lib/python3.7/site-packages/jinja2/environment.py", line 830, in get_template
    return self._load_template(name, self.make_globals(globals))
  File "/home/ubuntu/.local/lib/python3.7/site-packages/jinja2/environment.py", line 804, in _load_template
    template = self.loader.load(self, name, globals)
  File "/home/ubuntu/.local/lib/python3.7/site-packages/jinja2/loaders.py", line 125, in load
    code = environment.compile(source, name, filename)
  File "/home/ubuntu/.local/lib/python3.7/site-packages/jinja2/environment.py", line 591, in compile
    self.handle_exception(exc_info, source_hint=source_hint)
  File "/home/ubuntu/.local/lib/python3.7/site-packages/jinja2/environment.py", line 780, in handle_exception
    reraise(exc_type, exc_value, tb)
  File "/home/ubuntu/.local/lib/python3.7/site-packages/jinja2/_compat.py", line 37, in reraise
    raise value.with_traceback(tb)
  File "/home/ubuntu/blog/app/templates/base.html", line 80, in template
    {% block content %}
  File "/home/ubuntu/.local/lib/python3.7/site-packages/jinja2/environment.py", line 543, in _generate
    optimized=self.optimized)
  File "/home/ubuntu/.local/lib/python3.7/site-packages/jinja2/compiler.py", line 82, in generate
    generator.visit(node)
  File "/home/ubuntu/.local/lib/python3.7/site-packages/jinja2/visitor.py", line 38, in visit
    return f(node, *args, **kwargs)
  File "/home/ubuntu/.local/lib/python3.7/site-packages/jinja2/compiler.py", line 718, in visit_Template
    self.fail('block %r defined twice' % block.name, block.lineno)
  File "/home/ubuntu/.local/lib/python3.7/site-packages/jinja2/compiler.py", line 315, in fail
    raise TemplateAssertionError(msg, lineno, self.name, self.filename)
jinja2.exceptions.TemplateAssertionError: block 'content' defined twice
2019-12-01 11:58:42,570 INFO: 1st Woodhall Blog Startup [in /home/ubuntu/blog/app/__init__.py:66]
2019-12-01 12:02:44,188 INFO: 1st Woodhall Blog Startup [in /home/ubuntu/blog/app/__init__.py:66]
2019-12-01 12:03:24,795 INFO: 1st Woodhall Blog Startup [in /home/ubuntu/blog/app/__init__.py:66]
2019-12-01 12:06:24,996 INFO: 1st Woodhall Blog Startup [in /home/ubuntu/blog/app/__init__.py:66]
2019-12-01 12:07:23,579 INFO: 1st Woodhall Blog Startup [in /home/ubuntu/blog/app/__init__.py:66]
2019-12-01 12:07:40,508 INFO: 1st Woodhall Blog Startup [in /home/ubuntu/blog/app/__init__.py:66]
2019-12-01 12:08:35,295 INFO: 1st Woodhall Blog Startup [in /home/ubuntu/blog/app/__init__.py:66]
2019-12-01 12:09:32,404 INFO: 1st Woodhall Blog Startup [in /home/ubuntu/blog/app/__init__.py:66]
2019-12-01 12:09:51,507 INFO: 1st Woodhall Blog Startup [in /home/ubuntu/blog/app/__init__.py:66]
