2019-11-27 15:12:48,568 ERROR: Exception on /admin/ [GET] [in /home/ubuntu/.local/lib/python3.7/site-packages/flask/app.py:1891]
Traceback (most recent call last):
  File "/home/ubuntu/.local/lib/python3.7/site-packages/flask/app.py", line 2446, in wsgi_app
    response = self.full_dispatch_request()
  File "/home/ubuntu/.local/lib/python3.7/site-packages/flask/app.py", line 1951, in full_dispatch_request
    rv = self.handle_user_exception(e)
  File "/home/ubuntu/.local/lib/python3.7/site-packages/flask/app.py", line 1820, in handle_user_exception
    reraise(exc_type, exc_value, tb)
  File "/home/ubuntu/.local/lib/python3.7/site-packages/flask/_compat.py", line 39, in reraise
    raise value
  File "/home/ubuntu/.local/lib/python3.7/site-packages/flask/app.py", line 1949, in full_dispatch_request
    rv = self.dispatch_request()
  File "/home/ubuntu/.local/lib/python3.7/site-packages/flask/app.py", line 1935, in dispatch_request
    return self.view_functions[rule.endpoint](**req.view_args)
  File "/home/ubuntu/.local/lib/python3.7/site-packages/flask_admin/base.py", line 69, in inner
    return self._run_view(f, *args, **kwargs)
  File "/home/ubuntu/.local/lib/python3.7/site-packages/flask_admin/base.py", line 368, in _run_view
    return fn(self, *args, **kwargs)
  File "/home/ubuntu/.local/lib/python3.7/site-packages/flask_admin/base.py", line 452, in index
    return self.render(self._template)
  File "/home/ubuntu/.local/lib/python3.7/site-packages/flask_admin/base.py", line 308, in render
    return render_template(template, **kwargs)
  File "/home/ubuntu/.local/lib/python3.7/site-packages/flask/templating.py", line 140, in render_template
    ctx.app,
  File "/home/ubuntu/.local/lib/python3.7/site-packages/flask/templating.py", line 120, in _render
    rv = template.render(context)
  File "/home/ubuntu/.local/lib/python3.7/site-packages/jinja2/asyncsupport.py", line 76, in render
    return original_render(self, *args, **kwargs)
  File "/home/ubuntu/.local/lib/python3.7/site-packages/jinja2/environment.py", line 1008, in render
    return self.environment.handle_exception(exc_info, True)
  File "/home/ubuntu/.local/lib/python3.7/site-packages/jinja2/environment.py", line 780, in handle_exception
    reraise(exc_type, exc_value, tb)
  File "/home/ubuntu/.local/lib/python3.7/site-packages/jinja2/_compat.py", line 37, in reraise
    raise value.with_traceback(tb)
  File "/home/ubuntu/.local/lib/python3.7/site-packages/flask_admin/templates/bootstrap3/admin/index.html", line 1, in top-level template code
    {% extends 'admin/master.html' %}
  File "/home/ubuntu/.local/lib/python3.7/site-packages/jinja2/environment.py", line 1005, in render
    return concat(self.root_render_func(self.new_context(vars)))
  File "/home/ubuntu/.local/lib/python3.7/site-packages/flask_admin/templates/bootstrap3/admin/index.html", line 14, in root
  File "/home/ubuntu/.local/lib/python3.7/site-packages/flask_admin/templates/bootstrap3/admin/master.html", line 15, in root
  File "/home/ubuntu/.local/lib/python3.7/site-packages/flask_admin/templates/bootstrap3/admin/base.html", line 16, in root
    {%if config.get('FLASK_ADMIN_SWATCH', 'default') == 'default' %}
  File "/home/ubuntu/.local/lib/python3.7/site-packages/flask_admin/templates/bootstrap3/admin/base.html", line 44, in block_title
    <span class="sr-only">Toggle navigation</span>
  File "/home/ubuntu/.local/lib/python3.7/site-packages/markupsafe/_native.py", line 20, in escape
    if hasattr(s, '__html__'):
  File "/home/ubuntu/.local/lib/python3.7/site-packages/speaklater.py", line 177, in __getattr__
    return getattr(self.value, name)
  File "/home/ubuntu/.local/lib/python3.7/site-packages/speaklater.py", line 177, in __getattr__
    return getattr(self.value, name)
  File "/home/ubuntu/.local/lib/python3.7/site-packages/speaklater.py", line 177, in __getattr__
    return getattr(self.value, name)
  [Previous line repeated 471 more times]
  File "/home/ubuntu/.local/lib/python3.7/site-packages/speaklater.py", line 115, in <lambda>
    value = property(lambda x: x._func(*x._args, **x._kwargs))
  File "/home/ubuntu/.local/lib/python3.7/site-packages/flask_babelex/__init__.py", line 533, in gettext
    t = self.get_translations()
  File "/home/ubuntu/.local/lib/python3.7/site-packages/flask_babelex/__init__.py", line 510, in get_translations
    locale = get_locale()
  File "/home/ubuntu/.local/lib/python3.7/site-packages/flask_babelex/__init__.py", line 220, in get_locale
    rv = babel.locale_selector_func()
  File "/home/ubuntu/blog/app/__init__.py", line 69, in get_locale
    return request.accept_languages.best_match(current_app.config['LANGUAGES'])
  File "/home/ubuntu/.local/lib/python3.7/site-packages/werkzeug/local.py", line 348, in __getattr__
    return getattr(self._get_current_object(), name)
  File "/home/ubuntu/.local/lib/python3.7/site-packages/werkzeug/local.py", line 307, in _get_current_object
    return self.__local()
  File "/home/ubuntu/.local/lib/python3.7/site-packages/flask/globals.py", line 36, in _lookup_req_object
    top = _request_ctx_stack.top
  File "/home/ubuntu/.local/lib/python3.7/site-packages/werkzeug/local.py", line 169, in top
    return self._local.stack[-1]
  File "/home/ubuntu/.local/lib/python3.7/site-packages/werkzeug/local.py", line 72, in __getattr__
    return self.__storage__[self.__ident_func__()][name]
RecursionError: maximum recursion depth exceeded while calling a Python object
2019-11-27 15:23:03,700 INFO: 1st Woodhall Blog Startup [in /home/ubuntu/blog/app/__init__.py:61]
2019-11-27 17:03:17,718 INFO: 1st Woodhall Blog Startup [in /home/ubuntu/blog/app/__init__.py:61]
2019-11-27 17:24:36,185 INFO: 1st Woodhall Blog Startup [in /home/ubuntu/blog/app/__init__.py:59]
2019-11-27 17:35:34,190 INFO: 1st Woodhall Blog Startup [in /home/ubuntu/blog/app/__init__.py:57]
2019-11-27 17:36:11,883 INFO: 1st Woodhall Blog Startup [in /home/ubuntu/blog/app/__init__.py:57]
2019-11-27 17:36:40,274 ERROR: Exception on /auth/login [POST] [in /home/ubuntu/.local/lib/python3.7/site-packages/flask/app.py:1891]
Traceback (most recent call last):
  File "/home/ubuntu/.local/lib/python3.7/site-packages/flask/app.py", line 2446, in wsgi_app
    response = self.full_dispatch_request()
  File "/home/ubuntu/.local/lib/python3.7/site-packages/flask/app.py", line 1951, in full_dispatch_request
    rv = self.handle_user_exception(e)
  File "/home/ubuntu/.local/lib/python3.7/site-packages/flask/app.py", line 1820, in handle_user_exception
    reraise(exc_type, exc_value, tb)
  File "/home/ubuntu/.local/lib/python3.7/site-packages/flask/_compat.py", line 39, in reraise
    raise value
  File "/home/ubuntu/.local/lib/python3.7/site-packages/flask/app.py", line 1949, in full_dispatch_request
    rv = self.dispatch_request()
  File "/home/ubuntu/.local/lib/python3.7/site-packages/flask/app.py", line 1935, in dispatch_request
    return self.view_functions[rule.endpoint](**req.view_args)
  File "/home/ubuntu/blog/app/auth/routes.py", line 15, in login
    return redirect(url_for('main.home'))
  File "/home/ubuntu/.local/lib/python3.7/site-packages/flask/helpers.py", line 370, in url_for
    return appctx.app.handle_url_build_error(error, endpoint, values)
  File "/home/ubuntu/.local/lib/python3.7/site-packages/flask/app.py", line 2215, in handle_url_build_error
    reraise(exc_type, exc_value, tb)
  File "/home/ubuntu/.local/lib/python3.7/site-packages/flask/_compat.py", line 39, in reraise
    raise value
  File "/home/ubuntu/.local/lib/python3.7/site-packages/flask/helpers.py", line 358, in url_for
    endpoint, values, method=method, force_external=external
  File "/home/ubuntu/.local/lib/python3.7/site-packages/werkzeug/routing.py", line 2020, in build
    raise BuildError(endpoint, values, method, self)
werkzeug.routing.BuildError: Could not build url for endpoint 'main.home'. Did you mean 'main.user' instead?
2019-11-27 17:37:01,286 ERROR: Exception on /home [GET] [in /home/ubuntu/.local/lib/python3.7/site-packages/flask/app.py:1891]
Traceback (most recent call last):
  File "/home/ubuntu/.local/lib/python3.7/site-packages/flask/app.py", line 2446, in wsgi_app
    response = self.full_dispatch_request()
  File "/home/ubuntu/.local/lib/python3.7/site-packages/flask/app.py", line 1951, in full_dispatch_request
    rv = self.handle_user_exception(e)
  File "/home/ubuntu/.local/lib/python3.7/site-packages/flask/app.py", line 1820, in handle_user_exception
    reraise(exc_type, exc_value, tb)
  File "/home/ubuntu/.local/lib/python3.7/site-packages/flask/_compat.py", line 39, in reraise
    raise value
  File "/home/ubuntu/.local/lib/python3.7/site-packages/flask/app.py", line 1949, in full_dispatch_request
    rv = self.dispatch_request()
  File "/home/ubuntu/.local/lib/python3.7/site-packages/flask/app.py", line 1935, in dispatch_request
    return self.view_functions[rule.endpoint](**req.view_args)
  File "/home/ubuntu/.local/lib/python3.7/site-packages/flask_login/utils.py", line 261, in decorated_view
    return func(*args, **kwargs)
  File "/home/ubuntu/blog/app/main/routes.py", line 38, in index
    page, app.config['POSTS_PER_PAGE'], False)
NameError: name 'app' is not defined
2019-11-27 17:37:27,680 INFO: 1st Woodhall Blog Startup [in /home/ubuntu/blog/app/__init__.py:57]
