2019-11-24 17:36:22,886 ERROR: Exception on /edit_profile [GET] [in /home/ubuntu/.local/lib/python3.7/site-packages/flask/app.py:1891]
Traceback (most recent call last):
  File "/home/ubuntu/.local/lib/python3.7/site-packages/flask/app.py", line 2446, in wsgi_app
    response = self.full_dispatch_request()
  File "/home/ubuntu/.local/lib/python3.7/site-packages/flask/app.py", line 1951, in full_dispatch_request
    rv = self.handle_user_exception(e)
  File "/home/ubuntu/.local/lib/python3.7/site-packages/flask/app.py", line 1820, in handle_user_exception
    reraise(exc_type, exc_value, tb)
  File "/home/ubuntu/.local/lib/python3.7/site-packages/flask/_compat.py", line 39, in reraise
    raise value
  File "/home/ubuntu/.local/lib/python3.7/site-packages/flask/app.py", line 1949, in full_dispatch_request
    rv = self.dispatch_request()
  File "/home/ubuntu/.local/lib/python3.7/site-packages/flask/app.py", line 1935, in dispatch_request
    return self.view_functions[rule.endpoint](**req.view_args)
  File "/home/ubuntu/.local/lib/python3.7/site-packages/flask_login/utils.py", line 261, in decorated_view
    return func(*args, **kwargs)
  File "/home/ubuntu/blog/app/main/routes.py", line 94, in edit_profile
    form=form)
  File "/home/ubuntu/.local/lib/python3.7/site-packages/flask/templating.py", line 140, in render_template
    ctx.app,
  File "/home/ubuntu/.local/lib/python3.7/site-packages/flask/templating.py", line 120, in _render
    rv = template.render(context)
  File "/home/ubuntu/.local/lib/python3.7/site-packages/jinja2/asyncsupport.py", line 76, in render
    return original_render(self, *args, **kwargs)
  File "/home/ubuntu/.local/lib/python3.7/site-packages/jinja2/environment.py", line 1008, in render
    return self.environment.handle_exception(exc_info, True)
  File "/home/ubuntu/.local/lib/python3.7/site-packages/jinja2/environment.py", line 780, in handle_exception
    reraise(exc_type, exc_value, tb)
  File "/home/ubuntu/.local/lib/python3.7/site-packages/jinja2/_compat.py", line 37, in reraise
    raise value.with_traceback(tb)
  File "/home/ubuntu/blog/app/templates/edit_profile.html", line 2, in top-level template code
    {% import 'bootstrap/wtf.html' as wtf %}
  File "/home/ubuntu/.local/lib/python3.7/site-packages/jinja2/environment.py", line 1005, in render
    return concat(self.root_render_func(self.new_context(vars)))
  File "/home/ubuntu/blog/app/templates/edit_profile.html", line 17, in root
    </div>
  File "/home/ubuntu/blog/app/templates/base.html", line 14, in root
    {{ super() }}
  File "/home/ubuntu/.local/lib/python3.7/site-packages/flask_bootstrap/templates/bootstrap/base.html", line 10, in root
    <meta name="viewport" content="width=device-width, initial-scale=1.0">
  File "/home/ubuntu/.local/lib/python3.7/site-packages/flask_bootstrap/templates/bootstrap/base.html", line 20, in block_doc
    {% block body -%}
  File "/home/ubuntu/.local/lib/python3.7/site-packages/flask_bootstrap/templates/bootstrap/base.html", line 39, in block_html
  File "/home/ubuntu/.local/lib/python3.7/site-packages/flask_bootstrap/templates/bootstrap/base.html", line 92, in block_body
  File "/home/ubuntu/blog/app/templates/base.html", line 101, in block_content
    trigger: 'manual',
  File "/home/ubuntu/blog/app/templates/edit_profile.html", line 29, in block_app_content
  File "/home/ubuntu/.local/lib/python3.7/site-packages/jinja2/runtime.py", line 262, in call
    return __obj(*args, **kwargs)
  File "/home/ubuntu/.local/lib/python3.7/site-packages/jinja2/runtime.py", line 570, in __call__
    return self._invoke(arguments, autoescape)
  File "/home/ubuntu/.local/lib/python3.7/site-packages/jinja2/asyncsupport.py", line 110, in _invoke
    return original_invoke(self, arguments, autoescape)
  File "/home/ubuntu/.local/lib/python3.7/site-packages/jinja2/runtime.py", line 574, in _invoke
    rv = self._func(*arguments)
  File "/home/ubuntu/.local/lib/python3.7/site-packages/flask_bootstrap/templates/bootstrap/wtf.html", line 495, in macro
  File "/home/ubuntu/.local/lib/python3.7/site-packages/jinja2/runtime.py", line 262, in call
    return __obj(*args, **kwargs)
  File "/home/ubuntu/.local/lib/python3.7/site-packages/jinja2/runtime.py", line 570, in __call__
    return self._invoke(arguments, autoescape)
  File "/home/ubuntu/.local/lib/python3.7/site-packages/jinja2/asyncsupport.py", line 110, in _invoke
    return original_invoke(self, arguments, autoescape)
  File "/home/ubuntu/.local/lib/python3.7/site-packages/jinja2/runtime.py", line 574, in _invoke
    rv = self._func(*arguments)
  File "/home/ubuntu/.local/lib/python3.7/site-packages/flask_bootstrap/templates/bootstrap/wtf.html", line 342, in macro
  File "/home/ubuntu/.local/lib/python3.7/site-packages/jinja2/runtime.py", line 262, in call
    return __obj(*args, **kwargs)
  File "/home/ubuntu/.local/lib/python3.7/site-packages/wtforms/fields/core.py", line 155, in __call__
    return self.meta.render_field(self, kwargs)
  File "/home/ubuntu/.local/lib/python3.7/site-packages/wtforms/meta.py", line 56, in render_field
    return field.widget(field, **render_kw)
  File "/home/ubuntu/.local/lib/python3.7/site-packages/wtforms/widgets/core.py", line 323, in __call__
    for val, label, selected in field.iter_choices():
  File "/home/ubuntu/.local/lib/python3.7/site-packages/wtforms/fields/core.py", line 454, in iter_choices
    for value, label in self.choices:
TypeError: 'NoneType' object is not iterable
2019-11-24 17:41:34,489 INFO: Microblog startup [in /home/ubuntu/blog/app/__init__.py:66]
2019-11-24 17:42:10,185 INFO: Microblog startup [in /home/ubuntu/blog/app/__init__.py:66]
2019-11-24 17:46:58,766 INFO: Microblog startup [in /home/ubuntu/blog/app/__init__.py:66]
2019-11-24 17:47:06,388 INFO: Microblog startup [in /home/ubuntu/blog/app/__init__.py:66]
2019-11-24 17:48:00,891 INFO: Microblog startup [in /home/ubuntu/blog/app/__init__.py:66]
2019-11-24 17:48:09,781 INFO: Microblog startup [in /home/ubuntu/blog/app/__init__.py:66]
2019-11-24 17:48:21,207 INFO: Microblog startup [in /home/ubuntu/blog/app/__init__.py:66]
2019-11-24 17:50:30,079 INFO: Microblog startup [in /home/ubuntu/blog/app/__init__.py:66]
2019-11-24 17:51:21,186 ERROR: Exception on /edit_profile [POST] [in /home/ubuntu/.local/lib/python3.7/site-packages/flask/app.py:1891]
Traceback (most recent call last):
  File "/home/ubuntu/.local/lib/python3.7/site-packages/flask/app.py", line 2446, in wsgi_app
    response = self.full_dispatch_request()
  File "/home/ubuntu/.local/lib/python3.7/site-packages/flask/app.py", line 1951, in full_dispatch_request
    rv = self.handle_user_exception(e)
  File "/home/ubuntu/.local/lib/python3.7/site-packages/flask/app.py", line 1820, in handle_user_exception
    reraise(exc_type, exc_value, tb)
  File "/home/ubuntu/.local/lib/python3.7/site-packages/flask/_compat.py", line 39, in reraise
    raise value
  File "/home/ubuntu/.local/lib/python3.7/site-packages/flask/app.py", line 1949, in full_dispatch_request
    rv = self.dispatch_request()
  File "/home/ubuntu/.local/lib/python3.7/site-packages/flask/app.py", line 1935, in dispatch_request
    return self.view_functions[rule.endpoint](**req.view_args)
  File "/home/ubuntu/.local/lib/python3.7/site-packages/flask_login/utils.py", line 261, in decorated_view
    return func(*args, **kwargs)
  File "/home/ubuntu/blog/app/main/routes.py", line 91, in edit_profile
    return redirect(url_for('main.user'))
  File "/home/ubuntu/.local/lib/python3.7/site-packages/flask/helpers.py", line 370, in url_for
    return appctx.app.handle_url_build_error(error, endpoint, values)
  File "/home/ubuntu/.local/lib/python3.7/site-packages/flask/app.py", line 2215, in handle_url_build_error
    reraise(exc_type, exc_value, tb)
  File "/home/ubuntu/.local/lib/python3.7/site-packages/flask/_compat.py", line 39, in reraise
    raise value
  File "/home/ubuntu/.local/lib/python3.7/site-packages/flask/helpers.py", line 358, in url_for
    endpoint, values, method=method, force_external=external
  File "/home/ubuntu/.local/lib/python3.7/site-packages/werkzeug/routing.py", line 2020, in build
    raise BuildError(endpoint, values, method, self)
werkzeug.routing.BuildError: Could not build url for endpoint 'main.user'. Did you forget to specify values ['username']?
2019-11-24 17:53:53,676 INFO: Microblog startup [in /home/ubuntu/blog/app/__init__.py:66]
